Workbook

Sheet Dato
A1: Lluvia Efectiva | D1: Datos tecnoagro | E1: 25 de junio de 2024
A2: <15 mm | B2: 1 | E2: Humedad Actual | F2: % HUM | G2: % HUM | H2: Densidad | I2: Espesor | J2: Humedad Actual | K2: CC | L2: PMP | M2: AGUA UTIL | N2: Humedad
A3: 15-30 mm. | B3: 0.85 | E3: % | F3: CC | G3: PMP | H3: gr/cm3 | I3: dm | J3: mm | K3: mm | L3: mm | M3: mm | N3: perfil mm.
A4: 30-60 | B4: 0.7 | D4: 0-20cm | E4: 29 | F4: 25.7 | G4: 14.8 | H4: 1.31 | I4: 2 | J4: =E4*H4*I4 -> 75.98 | K4: =F4*H4*I4 -> 67.334 | L4: =G4*H4*I4 -> 38.776 | M4: =K4-L4 -> 28.558 | N4: =J4-L4 -> 37.204
A5: >60 | B5: 0.55 | D5: 20-40cm | E5: 22 | F5: 22.6 | G5: 15.1 | H5: 1.35 | I5: 2 | J5: =E5*H5*I5 -> 59.4 | K5: =F5*H5*I5 -> 61.02 | L5: =G5*H5*I5 -> 40.77 | M5: =K5-L5 -> 20.25 | N5: =J5-L5 -> 18.63
D6: 40-80cm | E6: 31 | F6: 31.3 | G6: 19.8 | H6: 1.4 | I6: 6 | J6: =E6*H6*I6 -> 260.4 | K6: =F6*H6*I6 -> 262.92 | L6: =G6*H6*I6 -> 166.32 | M6: =K6-L6 -> 96.6 | N6: =J6-L6 -> 94.08
D7: Total | M7: =SUM(M4:M6) -> 145.408 | N7: =SUM(N4:N6) -> 149.914
L8: Factor Ajuste | M8: 0.75
L9: AU Corregida | M9: =M7*M8 -> 109.056
A11: Inicial | B11: 45536 | C11: 0.05
B12: 45542 | C12: 0.09
B13: 45550 | C13: 0.14
B14: 45556 | C14: 0.18
B15: 45563 | C15: 0.25
A16: Crecimiento | B16: 45572 | C16: 0.28
B17: 45580 | C17: 0.44
B18: 45586 | C18: 0.51
B19: 45593 | C19: 0.64
B20: 45603 | C20: 0.77
B21: 45611 | C21: 0.84
A22: Desarrollo - PC | B22: 45617 | C22: 0.96
B23: 45624 | C23: 1
B24: 45633 | C24: 1.1
B25: 45641 | C25: 1.1
B26: 45647 | C26: 1.1
B27: 45654 | C27: 1
B28: 45664 | C28: 0.95
B29: 45672 | C29: 0.87
A30: Mad. Fisiologica | B30: 45678 | C30: 0.77
B31: 45685 | C31: 0.56

Sheet Hoja2
A1: Pivot | B1: SGR
A2: Fecha | B2: Estado Fenológico | C2: Riego(mm)
A3: 45946 | B3: Inicial | C3: 20
A4: 45994 | B4: Desarrollo - PC | C4: 20
A5: 45998 | B5: Desarrollo - PC | C5: 20
A6: 46001 | B6: Desarrollo - PC | C6: 20
A7: 46013 | B7: Desarrollo - PC | C7: 20
A10: Total | C10: =SUM(C3:C9) -> 100
B12: Pivot: SGR
B13: Fecha | C13: Lamina
B14: 45998 | C14: 20
B15: 46001 | C15: 20
B16: 46004 | C16: 20
B17: 46013 | C17: 20
B18: 46022 | C18: 20
B19: 46028 | C19: 20
B20: 46030 | C20: 20
B21: 46042 | C21: 20
B22: Total | C22: =SUM(C14:C21) -> 160
B23: Superficie | C23: 100
B24: MM total | C24: =C22*C23 -> 16000

Sheet Hoja1
A1: El Trebol - Riego - Maiz
A2: Lote | B2: Superficie | C2: F. Siembra | D2: Octubre | E2: Noviembre | F2: Diciembre | G2: Enero | H2: Febrero
A3: ET - SGR | B3: 100 | C3: 45917 | D3: =B3*SUM('ET - SGR'!C16:C46) -> 2000 | E3: =B3*SUM('ET - SGR'!C47:C76) -> 0 | F3: =B3*SUM('ET - SGR'!C77:C107) -> 12000 | G3: =B3*SUM('ET - SGR'!C108:C138) -> 6000 | H3: =B3*SUM('ET - SGR'!C139:C153) -> 0
A8: Total | B8: =SUM(B3:B7) -> 100 | D8: =SUM(D3:D7) -> 2000 | E8: =SUM(E3:E7) -> 0 | F8: =SUM(F3:F7) -> 12000 | G8: =SUM(G3:G7) -> 6000 | H8: =SUM(H3:H7) -> 0

Sheet ET - SGR
A1: Fecha | B1: Estado Fenológico | C1: Riego(mm) | D1: Lluvia (mm) | E1: Coef. | F1: Lluvia Ef. | G1: Acumulado | H1: ETP (mm) | I1: KC | J1: ETC.Cult. | K1: AU: Riego | L1: % Agua Útil | M1: Umbral | N1: AU-Umbral | O1: Acumulado PP | P1: AU: Secano | Q1: kc | R1: ETP | S1: ETC.Cult. | T1: DATOS: | V1: AU: PP (sin R)
A2: =Hoja1!C3 -> 45917 | B2: Emergencia | E2: 1 | F2: =D2*E2 -> 0 | G2: 90 | H2: 2.4 | I2: 0.09 | J2: =H2*I2 -> 0.216 | K2: =IF(C2+F2+G2-J2>$U$2,$U$2,(IF(C2+F2+G2-J2<0,0,C2+F2+G2-J2))) -> 89.784 | L2: =P2*100/$U$2 -> 74.82 | M2: =+$U$2*0.5 -> 60 | N2: =K2-M2 -> 29.784 | O2: =G2 -> 90 | P2: =IF(V2+F2+G2-J2>$U$2,$U$2,(IF(V2+F2+G2-J2<0,0,V2+F2+G2-J2))) -> 89.784 | Q2: Prom etapa | R2: Prom etapa | S2: Prom etapa | T2: Agua Útil | U2: 120
A3: =A2+1 -> 45918 | B3: Inicial | E3: 1 | F3: =D3*E3 -> 0 | G3: =K2 -> 89.784 | H3: 2.6 | I3: 0.09 | J3: =H3*I3 -> 0.234 | K3: =IF(C3+F3+G3-J3>$U$2,$U$2,(IF(C3+F3+G3-J3<0,0,C3+F3+G3-J3))) -> 89.55 | L3: =P3*100/$U$2 -> 74.625 | M3: =+$U$2*0.5 -> 60 | N3: =K3-M3 -> 29.55 | O3: =P2 -> 89.784 | P3: =IF(V3+F3+O3-J3>$U$2,$U$2,(IF(V3+F3+O3-J3<0,0,V3+F3+O3-J3))) -> 89.55
A4: =A3+1 -> 45919 | B4: Inicial | E4: 1 | F4: =D4*E4 -> 0 | G4: =K3 -> 89.55 | H4: 3 | I4: 0.09 | J4: =H4*I4 -> 0.27 | K4: =IF(C4+F4+G4-J4>$U$2,$U$2,(IF(C4+F4+G4-J4<0,0,C4+F4+G4-J4))) -> 89.28 | L4: =K4*100/$U$2 -> 74.4 | M4: =+$U$2*0.5 -> 60 | N4: =K4-M4 -> 29.28 | O4: =P3 -> 89.55 | P4: =IF(V4+F4+O4-J4>$U$2,$U$2,(IF(V4+F4+O4-J4<0,0,V4+F4+O4-J4))) -> 89.28 | T4: Notas:
A5: =A4+1 -> 45920 | B5: Inicial | E5: 1 | F5: =D5*E5 -> 0 | G5: =K4 -> 89.28 | H5: 2.55 | I5: 0.09 | J5: =H5*I5 -> 0.2295 | K5: =IF(C5+F5+G5-J5>$U$2,$U$2,(IF(C5+F5+G5-J5<0,0,C5+F5+G5-J5))) -> 89.0505 | L5: =K5*100/$U$2 -> 74.20875 | M5: =+$U$2*0.5 -> 60 | N5: =K5-M5 -> 29.0505 | O5: =P4 -> 89.28 | P5: =IF(V5+F5+O5-J5>$U$2,$U$2,(IF(V5+F5+O5-J5<0,0,V5+F5+O5-J5))) -> 89.0505 | T5: ETP | U5: Dato campaña 2015-16 Hidraulica ER Urdinarrain
A6: =A5+1 -> 45921 | B6: Inicial | D6: 22 | E6: 1 | F6: =D6*E6 -> 22 | G6: =K5 -> 89.0505 | H6: 4 | I6: 0.09 | J6: =H6*I6 -> 0.36 | K6: =IF(C6+F6+G6-J6>$U$2,$U$2,(IF(C6+F6+G6-J6<0,0,C6+F6+G6-J6))) -> 110.6905 | L6: =K6*100/$U$2 -> 92.242083 | M6: =+$U$2*0.5 -> 60 | N6: =K6-M6 -> 50.6905 | O6: =P5 -> 89.0505 | P6: =IF(V6+F6+O6-J6>$U$2,$U$2,(IF(V6+F6+O6-J6<0,0,V6+F6+O6-J6))) -> 110.6905 | T6: ETP | U6: Dato campaña 2014-15 Hidraulica ER Urdinarrain
A7: =A6+1 -> 45922 | B7: Inicial | E7: 1 | F7: =D7*E7 -> 0 | G7: =K6 -> 110.6905 | H7: 4.2 | I7: 0.09 | J7: =H7*I7 -> 0.378 | K7: =IF(C7+F7+G7-J7>$U$2,$U$2,(IF(C7+F7+G7-J7<0,0,C7+F7+G7-J7))) -> 110.3125 | L7: =K7*100/$U$2 -> 91.927083 | M7: =+$U$2*0.5 -> 60 | N7: =K7-M7 -> 50.3125 | O7: =P6 -> 110.6905 | P7: =IF(V7+F7+O7-J7>$U$2,$U$2,(IF(V7+F7+O7-J7<0,0,V7+F7+O7-J7))) -> 110.3125
A8: =A7+1 -> 45923 | B8: Inicial | E8: 1 | F8: =D8*E8 -> 0 | G8: =K7 -> 110.3125 | H8: 1.2 | I8: 0.09 | J8: =H8*I8 -> 0.108 | K8: =IF(C8+F8+G8-J8>$U$2,$U$2,(IF(C8+F8+G8-J8<0,0,C8+F8+G8-J8))) -> 110.2045 | L8: =K8*100/$U$2 -> 91.837083 | M8: =+$U$2*0.5 -> 60 | N8: =K8-M8 -> 50.2045 | O8: =P7 -> 110.3125 | P8: =IF(V8+F8+O8-J8>$U$2,$U$2,(IF(V8+F8+O8-J8<0,0,V8+F8+O8-J8))) -> 110.2045
A9: =A8+1 -> 45924 | B9: Inicial | E9: 1 | F9: =D9*E9 -> 0 | G9: =K8 -> 110.2045 | H9: 2.7 | I9: 0.09 | J9: =H9*I9 -> 0.243 | K9: =IF(C9+F9+G9-J9>$U$2,$U$2,(IF(C9+F9+G9-J9<0,0,C9+F9+G9-J9))) -> 109.9615 | L9: =K9*100/$U$2 -> 91.634583 | M9: =+$U$2*0.5 -> 60 | N9: =K9-M9 -> 49.9615 | O9: =P8 -> 110.2045 | P9: =IF(V9+F9+O9-J9>$U$2,$U$2,(IF(V9+F9+O9-J9<0,0,V9+F9+O9-J9))) -> 109.9615
A10: =A9+1 -> 45925 | B10: Inicial | E10: 1 | F10: =D10*E10 -> 0 | G10: =K9 -> 109.9615 | H10: 3.6 | I10: 0.14 | J10: =H10*I10 -> 0.504 | K10: =IF(C10+F10+G10-J10>$U$2,$U$2,(IF(C10+F10+G10-J10<0,0,C10+F10+G10-J10))) -> 109.4575 | L10: =K10*100/$U$2 -> 91.214583 | M10: =+$U$2*0.5 -> 60 | N10: =K10-M10 -> 49.4575 | O10: =P9 -> 109.9615 | P10: =IF(V10+F10+O10-J10>$U$2,$U$2,(IF(V10+F10+O10-J10<0,0,V10+F10+O10-J10))) -> 109.4575
A11: =A10+1 -> 45926 | B11: Inicial | E11: 1 | F11: =D11*E11 -> 0 | G11: =K10 -> 109.4575 | H11: 4.6 | I11: 0.14 | J11: =H11*I11 -> 0.644 | K11: =IF(C11+F11+G11-J11>$U$2,$U$2,(IF(C11+F11+G11-J11<0,0,C11+F11+G11-J11))) -> 108.8135 | L11: =K11*100/$U$2 -> 90.677917 | M11: =+$U$2*0.5 -> 60 | N11: =K11-M11 -> 48.8135 | O11: =P10 -> 109.4575 | P11: =IF(V11+F11+O11-J11>$U$2,$U$2,(IF(V11+F11+O11-J11<0,0,V11+F11+O11-J11))) -> 108.8135
A12: =A11+1 -> 45927 | B12: Inicial | E12: 1 | F12: =D12*E12 -> 0 | G12: =K11 -> 108.8135 | H12: 4 | I12: 0.14 | J12: =H12*I12 -> 0.56 | K12: =IF(C12+F12+G12-J12>$U$2,$U$2,(IF(C12+F12+G12-J12<0,0,C12+F12+G12-J12))) -> 108.2535 | L12: =K12*100/$U$2 -> 90.21125 | M12: =+$U$2*0.5 -> 60 | N12: =K12-M12 -> 48.2535 | O12: =P11 -> 108.8135 | P12: =IF(V12+F12+O12-J12>$U$2,$U$2,(IF(V12+F12+O12-J12<0,0,V12+F12+O12-J12))) -> 108.2535
A13: =A12+1 -> 45928 | B13: Inicial | E13: 1 | F13: =D13*E13 -> 0 | G13: =K12 -> 108.2535 | H13: 4.65 | I13: 0.14 | J13: =H13*I13 -> 0.651 | K13: =IF(C13+F13+G13-J13>$U$2,$U$2,(IF(C13+F13+G13-J13<0,0,C13+F13+G13-J13))) -> 107.6025 | L13: =K13*100/$U$2 -> 89.66875 | M13: =+$U$2*0.5 -> 60 | N13: =K13-M13 -> 47.6025 | O13: =P12 -> 108.2535 | P13: =IF(V13+F13+O13-J13>$U$2,$U$2,(IF(V13+F13+O13-J13<0,0,V13+F13+O13-J13))) -> 107.6025
A14: =A13+1 -> 45929 | B14: Inicial | E14: 1 | F14: =D14*E14 -> 0 | G14: =K13 -> 107.6025 | H14: 3.6 | I14: 0.14 | J14: =H14*I14 -> 0.504 | K14: =IF(C14+F14+G14-J14>$U$2,$U$2,(IF(C14+F14+G14-J14<0,0,C14+F14+G14-J14))) -> 107.0985 | L14: =K14*100/$U$2 -> 89.24875 | M14: =+$U$2*0.5 -> 60 | N14: =K14-M14 -> 47.0985 | O14: =P13 -> 107.6025 | P14: =IF(V14+F14+O14-J14>$U$2,$U$2,(IF(V14+F14+O14-J14<0,0,V14+F14+O14-J14))) -> 107.0985
A15: =A14+1 -> 45930 | B15: Inicial | E15: 1 | F15: =D15*E15 -> 0 | G15: =K14 -> 107.0985 | H15: 4.5 | I15: 0.14 | J15: =H15*I15 -> 0.63 | K15: =IF(C15+F15+G15-J15>$U$2,$U$2,(IF(C15+F15+G15-J15<0,0,C15+F15+G15-J15))) -> 106.4685 | L15: =K15*100/$U$2 -> 88.72375 | M15: =+$U$2*0.5 -> 60 | N15: =K15-M15 -> 46.4685 | O15: =P14 -> 107.0985 | P15: =IF(V15+F15+O15-J15>$U$2,$U$2,(IF(V15+F15+O15-J15<0,0,V15+F15+O15-J15))) -> 106.4685
A16: =A15+1 -> 45931 | B16: Inicial | E16: 1 | F16: =D16*E16 -> 0 | G16: =K15 -> 106.4685 | H16: 4.5 | I16: 0.18 | J16: =H16*I16 -> 0.81 | K16: =IF(C16+F16+G16-J16>$U$2,$U$2,(IF(C16+F16+G16-J16<0,0,C16+F16+G16-J16))) -> 105.6585 | L16: =K16*100/$U$2 -> 88.04875 | M16: =+$U$2*0.5 -> 60 | N16: =K16-M16 -> 45.6585 | O16: =P15 -> 106.4685 | P16: =IF(V16+F16+O16-J16>$U$2,$U$2,(IF(V16+F16+O16-J16<0,0,V16+F16+O16-J16))) -> 105.6585
A17: =A16+1 -> 45932 | B17: Inicial | E17: 1 | F17: =D17*E17 -> 0 | G17: =K16 -> 105.6585 | H17: 2.5 | I17: 0.18 | J17: =H17*I17 -> 0.45 | K17: =IF(C17+F17+G17-J17>$U$2,$U$2,(IF(C17+F17+G17-J17<0,0,C17+F17+G17-J17))) -> 105.2085 | L17: =K17*100/$U$2 -> 87.67375 | M17: =+$U$2*0.5 -> 60 | N17: =K17-M17 -> 45.2085 | O17: =P16 -> 105.6585 | P17: =IF(V17+F17+O17-J17>$U$2,$U$2,(IF(V17+F17+O17-J17<0,0,V17+F17+O17-J17))) -> 105.2085
A18: =A17+1 -> 45933 | B18: Inicial | E18: 1 | F18: =D18*E18 -> 0 | G18: =K17 -> 105.2085 | H18: 4 | I18: 0.18 | J18: =H18*I18 -> 0.72 | K18: =IF(C18+F18+G18-J18>$U$2,$U$2,(IF(C18+F18+G18-J18<0,0,C18+F18+G18-J18))) -> 104.4885 | L18: =K18*100/$U$2 -> 87.07375 | M18: =+$U$2*0.5 -> 60 | N18: =K18-M18 -> 44.4885 | O18: =P17 -> 105.2085 | P18: =IF(V18+F18+O18-J18>$U$2,$U$2,(IF(V18+F18+O18-J18<0,0,V18+F18+O18-J18))) -> 104.4885
A19: =A18+1 -> 45934 | B19: Inicial | E19: 1 | F19: =D19*E19 -> 0 | G19: =K18 -> 104.4885 | H19: 4.5 | I19: 0.18 | J19: =H19*I19 -> 0.81 | K19: =IF(C19+F19+G19-J19>$U$2,$U$2,(IF(C19+F19+G19-J19<0,0,C19+F19+G19-J19))) -> 103.6785 | L19: =K19*100/$U$2 -> 86.39875 | M19: =+$U$2*0.5 -> 60 | N19: =K19-M19 -> 43.6785 | O19: =P18 -> 104.4885 | P19: =IF(V19+F19+O19-J19>$U$2,$U$2,(IF(V19+F19+O19-J19<0,0,V19+F19+O19-J19))) -> 103.6785
A20: =A19+1 -> 45935 | B20: Inicial | D20: 32 | E20: 1 | F20: =D20*E20 -> 32 | G20: =K19 -> 103.6785 | H20: 5 | I20: 0.18 | J20: =H20*I20 -> 0.9 | K20: =IF(C20+F20+G20-J20>$U$2,$U$2,(IF(C20+F20+G20-J20<0,0,C20+F20+G20-J20))) -> 120 | L20: =K20*100/$U$2 -> 100 | M20: =+$U$2*0.5 -> 60 | N20: =K20-M20 -> 60 | O20: =P19 -> 103.6785 | P20: =IF(V20+F20+O20-J20>$U$2,$U$2,(IF(V20+F20+O20-J20<0,0,V20+F20+O20-J20))) -> 120
A21: =A20+1 -> 45936 | B21: Inicial | E21: 1 | F21: =D21*E21 -> 0 | G21: =K20 -> 120 | H21: 5.2 | I21: 0.18 | J21: =H21*I21 -> 0.936 | K21: =IF(C21+F21+G21-J21>$U$2,$U$2,(IF(C21+F21+G21-J21<0,0,C21+F21+G21-J21))) -> 119.064 | L21: =K21*100/$U$2 -> 99.22 | M21: =+$U$2*0.5 -> 60 | N21: =K21-M21 -> 59.064 | O21: =P20 -> 120 | P21: =IF(V21+F21+O21-J21>$U$2,$U$2,(IF(V21+F21+O21-J21<0,0,V21+F21+O21-J21))) -> 119.064
A22: =A21+1 -> 45937 | B22: Inicial | E22: 1 | F22: =D22*E22 -> 0 | G22: =K21 -> 119.064 | H22: 5.2 | I22: 0.18 | J22: =H22*I22 -> 0.936 | K22: =IF(C22+F22+G22-J22>$U$2,$U$2,(IF(C22+F22+G22-J22<0,0,C22+F22+G22-J22))) -> 118.128 | L22: =K22*100/$U$2 -> 98.44 | M22: =+$U$2*0.5 -> 60 | N22: =K22-M22 -> 58.128 | O22: =P21 -> 119.064 | P22: =IF(V22+F22+O22-J22>$U$2,$U$2,(IF(V22+F22+O22-J22<0,0,V22+F22+O22-J22))) -> 118.128
A23: =A22+1 -> 45938 | B23: Inicial | E23: 1 | F23: =D23*E23 -> 0 | G23: =K22 -> 118.128 | H23: 4.8 | I23: 0.18 | J23: =H23*I23 -> 0.864 | K23: =IF(C23+F23+G23-J23>$U$2,$U$2,(IF(C23+F23+G23-J23<0,0,C23+F23+G23-J23))) -> 117.264 | L23: =K23*100/$U$2 -> 97.72 | M23: =+$U$2*0.5 -> 60 | N23: =K23-M23 -> 57.264 | O23: =P22 -> 118.128 | P23: =IF(V23+F23+O23-J23>$U$2,$U$2,(IF(V23+F23+O23-J23<0,0,V23+F23+O23-J23))) -> 117.264
A24: =A23+1 -> 45939 | B24: Inicial | E24: 1 | F24: =D24*E24 -> 0 | G24: =K23 -> 117.264 | H24: 3 | I24: 0.25 | J24: =H24*I24 -> 0.75 | K24: =IF(C24+F24+G24-J24>$U$2,$U$2,(IF(C24+F24+G24-J24<0,0,C24+F24+G24-J24))) -> 116.514 | L24: =K24*100/$U$2 -> 97.095 | M24: =+$U$2*0.5 -> 60 | N24: =K24-M24 -> 56.514 | O24: =P23 -> 117.264 | P24: =IF(V24+F24+O24-J24>$U$2,$U$2,(IF(V24+F24+O24-J24<0,0,V24+F24+O24-J24))) -> 116.514
A25: =A24+1 -> 45940 | B25: Inicial | E25: 1 | F25: =D25*E25 -> 0 | G25: =K24 -> 116.514 | H25: 5.2 | I25: 0.25 | J25: =H25*I25 -> 1.3 | K25: =IF(C25+F25+G25-J25>$U$2,$U$2,(IF(C25+F25+G25-J25<0,0,C25+F25+G25-J25))) -> 115.214 | L25: =K25*100/$U$2 -> 96.011667 | M25: =+$U$2*0.5 -> 60 | N25: =K25-M25 -> 55.214 | O25: =P24 -> 116.514 | P25: =IF(V25+F25+O25-J25>$U$2,$U$2,(IF(V25+F25+O25-J25<0,0,V25+F25+O25-J25))) -> 115.214
A26: =A25+1 -> 45941 | B26: Inicial | E26: 1 | F26: =D26*E26 -> 0 | G26: =K25 -> 115.214 | H26: 5.1 | I26: 0.25 | J26: =H26*I26 -> 1.275 | K26: =IF(C26+F26+G26-J26>$U$2,$U$2,(IF(C26+F26+G26-J26<0,0,C26+F26+G26-J26))) -> 113.939 | L26: =K26*100/$U$2 -> 94.949167 | M26: =+$U$2*0.5 -> 60 | N26: =K26-M26 -> 53.939 | O26: =P25 -> 115.214 | P26: =IF(V26+F26+O26-J26>$U$2,$U$2,(IF(V26+F26+O26-J26<0,0,V26+F26+O26-J26))) -> 113.939
A27: =A26+1 -> 45942 | B27: Inicial | E27: 1 | F27: =D27*E27 -> 0 | G27: =K26 -> 113.939 | H27: 5 | I27: 0.25 | J27: =H27*I27 -> 1.25 | K27: =IF(C27+F27+G27-J27>$U$2,$U$2,(IF(C27+F27+G27-J27<0,0,C27+F27+G27-J27))) -> 112.689 | L27: =K27*100/$U$2 -> 93.9075 | M27: =+$U$2*0.5 -> 60 | N27: =K27-M27 -> 52.689 | O27: =P26 -> 113.939 | P27: =IF(V27+F27+O27-J27>$U$2,$U$2,(IF(V27+F27+O27-J27<0,0,V27+F27+O27-J27))) -> 112.689
A28: =A27+1 -> 45943 | B28: Inicial | E28: 1 | F28: =D28*E28 -> 0 | G28: =K27 -> 112.689 | H28: 5 | I28: 0.25 | J28: =H28*I28 -> 1.25 | K28: =IF(C28+F28+G28-J28>$U$2,$U$2,(IF(C28+F28+G28-J28<0,0,C28+F28+G28-J28))) -> 111.439 | L28: =K28*100/$U$2 -> 92.865833 | M28: =+$U$2*0.5 -> 60 | N28: =K28-M28 -> 51.439 | O28: =P27 -> 112.689 | P28: =IF(V28+F28+O28-J28>$U$2,$U$2,(IF(V28+F28+O28-J28<0,0,V28+F28+O28-J28))) -> 111.439
A29: =A28+1 -> 45944 | B29: Inicial | E29: 1 | F29: =D29*E29 -> 0 | G29: =K28 -> 111.439 | H29: 5 | I29: 0.25 | J29: =H29*I29 -> 1.25 | K29: =IF(C29+F29+G29-J29>$U$2,$U$2,(IF(C29+F29+G29-J29<0,0,C29+F29+G29-J29))) -> 110.189 | L29: =K29*100/$U$2 -> 91.824167 | M29: =+$U$2*0.5 -> 60 | N29: =K29-M29 -> 50.189 | O29: =P28 -> 111.439 | P29: =IF(V29+F29+O29-J29>$U$2,$U$2,(IF(V29+F29+O29-J29<0,0,V29+F29+O29-J29))) -> 110.189
A30: =A29+1 -> 45945 | B30: Inicial | E30: 1 | F30: =D30*E30 -> 0 | G30: =K29 -> 110.189 | H30: 5 | I30: 0.25 | J30: =H30*I30 -> 1.25 | K30: =IF(C30+F30+G30-J30>$U$2,$U$2,(IF(C30+F30+G30-J30<0,0,C30+F30+G30-J30))) -> 108.939 | L30: =K30*100/$U$2 -> 90.7825 | M30: =+$U$2*0.5 -> 60 | N30: =K30-M30 -> 48.939 | O30: =P29 -> 110.189 | P30: =IF(V30+F30+O30-J30>$U$2,$U$2,(IF(V30+F30+O30-J30<0,0,V30+F30+O30-J30))) -> 108.939
A31: =A30+1 -> 45946 | B31: Inicial | C31: 20 | E31: 1 | F31: =D31*E31 -> 0 | G31: =K30 -> 108.939 | H31: 5.1 | I31: 0.25 | J31: =H31*I31 -> 1.275 | K31: =IF(C31+F31+G31-J31>$U$2,$U$2,(IF(C31+F31+G31-J31<0,0,C31+F31+G31-J31))) -> 120 | L31: =K31*100/$U$2 -> 100 | M31: =+$U$2*0.5 -> 60 | N31: =K31-M31 -> 60 | O31: =P30 -> 108.939 | P31: =IF(V31+F31+O31-J31>$U$2,$U$2,(IF(V31+F31+O31-J31<0,0,V31+F31+O31-J31))) -> 107.664
A32: =A31+1 -> 45947 | B32: Inicial | E32: 1 | F32: =D32*E32 -> 0 | G32: =K31 -> 120 | H32: 5.7 | I32: 0.25 | J32: =H32*I32 -> 1.425 | K32: =IF(C32+F32+G32-J32>$U$2,$U$2,(IF(C32+F32+G32-J32<0,0,C32+F32+G32-J32))) -> 118.575 | L32: =K32*100/$U$2 -> 98.8125 | M32: =+$U$2*0.5 -> 60 | N32: =K32-M32 -> 58.575 | O32: =P31 -> 107.664 | P32: =IF(V32+F32+O32-J32>$U$2,$U$2,(IF(V32+F32+O32-J32<0,0,V32+F32+O32-J32))) -> 106.239 | Q32: =AVERAGE(I2:I31) -> 0.16666667 | R32: =AVERAGE(H2:H31) -> 4.0566667 | S32: =AVERAGE(J2:J32) -> 0.74137097
A33: =A32+1 -> 45948 | B33: Crecimiento | E33: 1 | F33: =D33*E33 -> 0 | G33: =K32 -> 118.575 | H33: 6 | I33: 0.44 | J33: =H33*I33 -> 2.64 | K33: =IF(C33+F33+G33-J33>$U$2,$U$2,(IF(C33+F33+G33-J33<0,0,C33+F33+G33-J33))) -> 115.935 | L33: =K33*100/$U$2 -> 96.6125 | M33: =+$U$2*0.5 -> 60 | N33: =K33-M33 -> 55.935 | O33: =P32 -> 106.239 | P33: =IF(V33+F33+O33-J33>$U$2,$U$2,(IF(V33+F33+O33-J33<0,0,V33+F33+O33-J33))) -> 103.599
A34: =A33+1 -> 45949 | B34: Crecimiento | E34: 1 | F34: =D34*E34 -> 0 | G34: =K33 -> 115.935 | H34: 4.3 | I34: 0.44 | J34: =H34*I34 -> 1.892 | K34: =IF(C34+F34+G34-J34>$U$2,$U$2,(IF(C34+F34+G34-J34<0,0,C34+F34+G34-J34))) -> 114.043 | L34: =K34*100/$U$2 -> 95.035833 | M34: =+$U$2*0.5 -> 60 | N34: =K34-M34 -> 54.043 | O34: =P33 -> 103.599 | P34: =IF(V34+F34+O34-J34>$U$2,$U$2,(IF(V34+F34+O34-J34<0,0,V34+F34+O34-J34))) -> 101.707
A35: =A34+1 -> 45950 | B35: Crecimiento | E35: 1 | F35: =D35*E35 -> 0 | G35: =K34 -> 114.043 | H35: 5.8 | I35: 0.44 | J35: =H35*I35 -> 2.552 | K35: =IF(C35+F35+G35-J35>$U$2,$U$2,(IF(C35+F35+G35-J35<0,0,C35+F35+G35-J35))) -> 111.491 | L35: =K35*100/$U$2 -> 92.909167 | M35: =+$U$2*0.5 -> 60 | N35: =K35-M35 -> 51.491 | O35: =P34 -> 101.707 | P35: =IF(V35+F35+O35-J35>$U$2,$U$2,(IF(V35+F35+O35-J35<0,0,V35+F35+O35-J35))) -> 99.155
A36: =A35+1 -> 45951 | B36: Crecimiento | E36: 1 | F36: =D36*E36 -> 0 | G36: =K35 -> 111.491 | H36: 1.9 | I36: 0.44 | J36: =H36*I36 -> 0.836 | K36: =IF(C36+F36+G36-J36>$U$2,$U$2,(IF(C36+F36+G36-J36<0,0,C36+F36+G36-J36))) -> 110.655 | L36: =K36*100/$U$2 -> 92.2125 | M36: =+$U$2*0.5 -> 60 | N36: =K36-M36 -> 50.655 | O36: =P35 -> 99.155 | P36: =IF(V36+F36+O36-J36>$U$2,$U$2,(IF(V36+F36+O36-J36<0,0,V36+F36+O36-J36))) -> 98.319
A37: =A36+1 -> 45952 | B37: Crecimiento | E37: 1 | F37: =D37*E37 -> 0 | G37: =K36 -> 110.655 | H37: 1.9 | I37: 0.44 | J37: =H37*I37 -> 0.836 | K37: =IF(C37+F37+G37-J37>$U$2,$U$2,(IF(C37+F37+G37-J37<0,0,C37+F37+G37-J37))) -> 109.819 | L37: =K37*100/$U$2 -> 91.515833 | M37: =+$U$2*0.5 -> 60 | N37: =K37-M37 -> 49.819 | O37: =P36 -> 98.319 | P37: =IF(V37+F37+O37-J37>$U$2,$U$2,(IF(V37+F37+O37-J37<0,0,V37+F37+O37-J37))) -> 97.483
A38: =A37+1 -> 45953 | B38: Crecimiento | E38: 1 | F38: =D38*E38 -> 0 | G38: =K37 -> 109.819 | H38: 4.8 | I38: 0.44 | J38: =H38*I38 -> 2.112 | K38: =IF(C38+F38+G38-J38>$U$2,$U$2,(IF(C38+F38+G38-J38<0,0,C38+F38+G38-J38))) -> 107.707 | L38: =K38*100/$U$2 -> 89.755833 | M38: =+$U$2*0.5 -> 60 | N38: =K38-M38 -> 47.707 | O38: =P37 -> 97.483 | P38: =IF(V38+F38+O38-J38>$U$2,$U$2,(IF(V38+F38+O38-J38<0,0,V38+F38+O38-J38))) -> 95.371
A39: =A38+1 -> 45954 | B39: Crecimiento | D39: 65 | E39: 0.8 | F39: =D39*E39 -> 52 | G39: =K38 -> 107.707 | H39: 3.2 | I39: 0.44 | J39: =H39*I39 -> 1.408 | K39: =IF(C39+F39+G39-J39>$U$2,$U$2,(IF(C39+F39+G39-J39<0,0,C39+F39+G39-J39))) -> 120 | L39: =K39*100/$U$2 -> 100 | M39: =+$U$2*0.5 -> 60 | N39: =K39-M39 -> 60 | O39: =P38 -> 95.371 | P39: =IF(V39+F39+O39-J39>$U$2,$U$2,(IF(V39+F39+O39-J39<0,0,V39+F39+O39-J39))) -> 120
A40: =A39+1 -> 45955 | B40: Crecimiento | E40: 1 | F40: =D40*E40 -> 0 | G40: =K39 -> 120 | H40: 2.7 | I40: 0.51 | J40: =H40*I40 -> 1.377 | K40: =IF(C40+F40+G40-J40>$U$2,$U$2,(IF(C40+F40+G40-J40<0,0,C40+F40+G40-J40))) -> 118.623 | L40: =K40*100/$U$2 -> 98.8525 | M40: =+$U$2*0.5 -> 60 | N40: =K40-M40 -> 58.623 | O40: =P39 -> 120 | P40: =IF(V40+F40+O40-J40>$U$2,$U$2,(IF(V40+F40+O40-J40<0,0,V40+F40+O40-J40))) -> 118.623
...

Sheet Graficos (2)

Sheet Hoja8
